[2020-07-14 14:47:25 +0800] [15661] [INFO] Starting gunicorn 20.0.4
[2020-07-14 14:47:25 +0800] [15661] [INFO] Listening at: http://0.0.0.0:5000 (15661)
[2020-07-14 14:47:25 +0800] [15661] [INFO] Using worker: gevent
[2020-07-14 14:47:25 +0800] [15664] [INFO] Booting worker with pid: 15664
[2020-07-14 14:47:25 +0800] [15665] [INFO] Booting worker with pid: 15665
[2020-07-14 15:31:20 +0800] [15664] [INFO] Worker reloading: gunicorn.conf modified
[2020-07-14 15:31:20 +0800] [15664] [INFO] Worker exiting (pid: 15664)
[2020-07-14 15:31:20 +0800] [15665] [INFO] Worker reloading: gunicorn.conf modified
[2020-07-14 15:31:20 +0800] [15665] [INFO] Worker exiting (pid: 15665)
[2020-07-14 15:31:20 +0800] [7276] [INFO] Booting worker with pid: 7276
[2020-07-14 15:31:20 +0800] [7277] [INFO] Booting worker with pid: 7277
[2020-07-17 11:32:37 +0800] [7277] [INFO] Worker reloading: /root/flask_python37/web/run.py modified
[2020-07-17 11:32:37 +0800] [7277] [INFO] Worker exiting (pid: 7277)
[2020-07-17 11:32:37 +0800] [7276] [INFO] Worker reloading: /root/flask_python37/web/run.py modified
[2020-07-17 11:32:37 +0800] [7276] [INFO] Worker exiting (pid: 7276)
[2020-07-17 11:32:37 +0800] [16749] [INFO] Booting worker with pid: 16749
[2020-07-17 11:32:37 +0800] [16750] [INFO] Booting worker with pid: 16750
[2020-07-17 11:32:38 +0800] [16750] [ERROR] Exception in worker process
Traceback (most recent call last):
  File "/root/flask_python37/lib/python3.7/site-packages/gunicorn/arbiter.py", line 583, in spawn_worker
    worker.init_process()
  File "/root/flask_python37/lib/python3.7/site-packages/gunicorn/workers/ggevent.py", line 162, in init_process
    super().init_process()
  File "/root/flask_python37/lib/python3.7/site-packages/gunicorn/workers/base.py", line 119, in init_process
    self.load_wsgi()
  File "/root/flask_python37/lib/python3.7/site-packages/gunicorn/workers/base.py", line 144, in load_wsgi
    self.wsgi = self.app.wsgi()
  File "/root/flask_python37/lib/python3.7/site-packages/gunicorn/app/base.py", line 67, in wsgi
    self.callable = self.load()
  File "/root/flask_python37/lib/python3.7/site-packages/gunicorn/app/wsgiapp.py", line 49, in load
    return self.load_wsgiapp()
  File "/root/flask_python37/lib/python3.7/site-packages/gunicorn/app/wsgiapp.py", line 39, in load_wsgiapp
    return util.import_app(self.app_uri)
  File "/root/flask_python37/lib/python3.7/site-packages/gunicorn/util.py", line 358, in import_app
    mod = importlib.import_module(module)
  File "/root/flask_python37/lib/python3.7/importlib/__init__.py", line 127, in import_module
    return _bootstrap._gcd_import(name[level:], package, level)
  File "<frozen importlib._bootstrap>", line 1006, in _gcd_import
  File "<frozen importlib._bootstrap>", line 983, in _find_and_load
  File "<frozen importlib._bootstrap>", line 967, in _find_and_load_unlocked
  File "<frozen importlib._bootstrap>", line 677, in _load_unlocked
  File "<frozen importlib._bootstrap_external>", line 728, in exec_module
  File "<frozen importlib._bootstrap>", line 219, in _call_with_frames_removed
  File "/root/flask_python37/web/run.py", line 25, in <module>
    @app.route("index.html")
  File "/root/flask_python37/lib/python3.7/site-packages/flask/app.py", line 1315, in decorator
    self.add_url_rule(rule, endpoint, f, **options)
  File "/root/flask_python37/lib/python3.7/site-packages/flask/app.py", line 98, in wrapper_func
    return f(self, *args, **kwargs)
  File "/root/flask_python37/lib/python3.7/site-packages/flask/app.py", line 1275, in add_url_rule
    rule = self.url_rule_class(rule, methods=methods, **options)
  File "/root/flask_python37/lib/python3.7/site-packages/werkzeug/routing.py", line 666, in __init__
    raise ValueError("urls must start with a leading slash")
ValueError: urls must start with a leading slash
[2020-07-17 11:32:38 +0800] [16750] [INFO] Worker exiting (pid: 16750)
[2020-07-17 11:32:38 +0800] [16749] [ERROR] Exception in worker process
Traceback (most recent call last):
  File "/root/flask_python37/lib/python3.7/site-packages/gunicorn/arbiter.py", line 583, in spawn_worker
    worker.init_process()
  File "/root/flask_python37/lib/python3.7/site-packages/gunicorn/workers/ggevent.py", line 162, in init_process
    super().init_process()
  File "/root/flask_python37/lib/python3.7/site-packages/gunicorn/workers/base.py", line 119, in init_process
    self.load_wsgi()
  File "/root/flask_python37/lib/python3.7/site-packages/gunicorn/workers/base.py", line 144, in load_wsgi
    self.wsgi = self.app.wsgi()
  File "/root/flask_python37/lib/python3.7/site-packages/gunicorn/app/base.py", line 67, in wsgi
    self.callable = self.load()
  File "/root/flask_python37/lib/python3.7/site-packages/gunicorn/app/wsgiapp.py", line 49, in load
    return self.load_wsgiapp()
  File "/root/flask_python37/lib/python3.7/site-packages/gunicorn/app/wsgiapp.py", line 39, in load_wsgiapp
    return util.import_app(self.app_uri)
  File "/root/flask_python37/lib/python3.7/site-packages/gunicorn/util.py", line 358, in import_app
    mod = importlib.import_module(module)
  File "/root/flask_python37/lib/python3.7/importlib/__init__.py", line 127, in import_module
    return _bootstrap._gcd_import(name[level:], package, level)
  File "<frozen importlib._bootstrap>", line 1006, in _gcd_import
  File "<frozen importlib._bootstrap>", line 983, in _find_and_load
  File "<frozen importlib._bootstrap>", line 967, in _find_and_load_unlocked
  File "<frozen importlib._bootstrap>", line 677, in _load_unlocked
  File "<frozen importlib._bootstrap_external>", line 728, in exec_module
  File "<frozen importlib._bootstrap>", line 219, in _call_with_frames_removed
  File "/root/flask_python37/web/run.py", line 25, in <module>
    @app.route("index.html")
  File "/root/flask_python37/lib/python3.7/site-packages/flask/app.py", line 1315, in decorator
    self.add_url_rule(rule, endpoint, f, **options)
  File "/root/flask_python37/lib/python3.7/site-packages/flask/app.py", line 98, in wrapper_func
    return f(self, *args, **kwargs)
  File "/root/flask_python37/lib/python3.7/site-packages/flask/app.py", line 1275, in add_url_rule
    rule = self.url_rule_class(rule, methods=methods, **options)
  File "/root/flask_python37/lib/python3.7/site-packages/werkzeug/routing.py", line 666, in __init__
    raise ValueError("urls must start with a leading slash")
ValueError: urls must start with a leading slash
[2020-07-17 11:32:38 +0800] [16749] [INFO] Worker exiting (pid: 16749)
[2020-07-17 11:32:38 +0800] [15661] [INFO] Shutting down: Master
[2020-07-17 11:32:38 +0800] [15661] [INFO] Reason: Worker failed to boot.
[2020-07-17 11:36:28 +0800] [17597] [INFO] Starting gunicorn 20.0.4
[2020-07-17 11:36:28 +0800] [17597] [INFO] Listening at: http://0.0.0.0:5000 (17597)
[2020-07-17 11:36:28 +0800] [17597] [INFO] Using worker: gevent
[2020-07-17 11:36:28 +0800] [17600] [INFO] Booting worker with pid: 17600
[2020-07-17 11:36:28 +0800] [17601] [INFO] Booting worker with pid: 17601
[2020-07-17 11:36:28 +0800] [17600] [ERROR] Exception in worker process
Traceback (most recent call last):
  File "/root/flask_python37/lib/python3.7/site-packages/gunicorn/arbiter.py", line 583, in spawn_worker
    worker.init_process()
  File "/root/flask_python37/lib/python3.7/site-packages/gunicorn/workers/ggevent.py", line 162, in init_process
    super().init_process()
  File "/root/flask_python37/lib/python3.7/site-packages/gunicorn/workers/base.py", line 119, in init_process
    self.load_wsgi()
  File "/root/flask_python37/lib/python3.7/site-packages/gunicorn/workers/base.py", line 144, in load_wsgi
    self.wsgi = self.app.wsgi()
  File "/root/flask_python37/lib/python3.7/site-packages/gunicorn/app/base.py", line 67, in wsgi
    self.callable = self.load()
  File "/root/flask_python37/lib/python3.7/site-packages/gunicorn/app/wsgiapp.py", line 49, in load
    return self.load_wsgiapp()
  File "/root/flask_python37/lib/python3.7/site-packages/gunicorn/app/wsgiapp.py", line 39, in load_wsgiapp
    return util.import_app(self.app_uri)
  File "/root/flask_python37/lib/python3.7/site-packages/gunicorn/util.py", line 358, in import_app
    mod = importlib.import_module(module)
  File "/root/flask_python37/lib/python3.7/importlib/__init__.py", line 127, in import_module
    return _bootstrap._gcd_import(name[level:], package, level)
  File "<frozen importlib._bootstrap>", line 1006, in _gcd_import
  File "<frozen importlib._bootstrap>", line 983, in _find_and_load
  File "<frozen importlib._bootstrap>", line 967, in _find_and_load_unlocked
  File "<frozen importlib._bootstrap>", line 677, in _load_unlocked
  File "<frozen importlib._bootstrap_external>", line 728, in exec_module
  File "<frozen importlib._bootstrap>", line 219, in _call_with_frames_removed
  File "/root/flask_python37/web/run.py", line 25, in <module>
    @app.route("index.html")
  File "/root/flask_python37/lib/python3.7/site-packages/flask/app.py", line 1315, in decorator
    self.add_url_rule(rule, endpoint, f, **options)
  File "/root/flask_python37/lib/python3.7/site-packages/flask/app.py", line 98, in wrapper_func
    return f(self, *args, **kwargs)
  File "/root/flask_python37/lib/python3.7/site-packages/flask/app.py", line 1275, in add_url_rule
    rule = self.url_rule_class(rule, methods=methods, **options)
  File "/root/flask_python37/lib/python3.7/site-packages/werkzeug/routing.py", line 666, in __init__
    raise ValueError("urls must start with a leading slash")
ValueError: urls must start with a leading slash
[2020-07-17 11:36:28 +0800] [17600] [INFO] Worker exiting (pid: 17600)
[2020-07-17 11:36:28 +0800] [17601] [ERROR] Exception in worker process
Traceback (most recent call last):
  File "/root/flask_python37/lib/python3.7/site-packages/gunicorn/arbiter.py", line 583, in spawn_worker
    worker.init_process()
  File "/root/flask_python37/lib/python3.7/site-packages/gunicorn/workers/ggevent.py", line 162, in init_process
    super().init_process()
  File "/root/flask_python37/lib/python3.7/site-packages/gunicorn/workers/base.py", line 119, in init_process
    self.load_wsgi()
  File "/root/flask_python37/lib/python3.7/site-packages/gunicorn/workers/base.py", line 144, in load_wsgi
    self.wsgi = self.app.wsgi()
  File "/root/flask_python37/lib/python3.7/site-packages/gunicorn/app/base.py", line 67, in wsgi
    self.callable = self.load()
  File "/root/flask_python37/lib/python3.7/site-packages/gunicorn/app/wsgiapp.py", line 49, in load
    return self.load_wsgiapp()
  File "/root/flask_python37/lib/python3.7/site-packages/gunicorn/app/wsgiapp.py", line 39, in load_wsgiapp
    return util.import_app(self.app_uri)
  File "/root/flask_python37/lib/python3.7/site-packages/gunicorn/util.py", line 358, in import_app
    mod = importlib.import_module(module)
  File "/root/flask_python37/lib/python3.7/importlib/__init__.py", line 127, in import_module
    return _bootstrap._gcd_import(name[level:], package, level)
  File "<frozen importlib._bootstrap>", line 1006, in _gcd_import
  File "<frozen importlib._bootstrap>", line 983, in _find_and_load
  File "<frozen importlib._bootstrap>", line 967, in _find_and_load_unlocked
  File "<frozen importlib._bootstrap>", line 677, in _load_unlocked
  File "<frozen importlib._bootstrap_external>", line 728, in exec_module
  File "<frozen importlib._bootstrap>", line 219, in _call_with_frames_removed
  File "/root/flask_python37/web/run.py", line 25, in <module>
    @app.route("index.html")
  File "/root/flask_python37/lib/python3.7/site-packages/flask/app.py", line 1315, in decorator
    self.add_url_rule(rule, endpoint, f, **options)
  File "/root/flask_python37/lib/python3.7/site-packages/flask/app.py", line 98, in wrapper_func
    return f(self, *args, **kwargs)
  File "/root/flask_python37/lib/python3.7/site-packages/flask/app.py", line 1275, in add_url_rule
    rule = self.url_rule_class(rule, methods=methods, **options)
  File "/root/flask_python37/lib/python3.7/site-packages/werkzeug/routing.py", line 666, in __init__
    raise ValueError("urls must start with a leading slash")
ValueError: urls must start with a leading slash
[2020-07-17 11:36:28 +0800] [17601] [INFO] Worker exiting (pid: 17601)
[2020-07-17 11:39:34 +0800] [18263] [INFO] Starting gunicorn 20.0.4
[2020-07-17 11:39:34 +0800] [18263] [INFO] Listening at: http://0.0.0.0:5000 (18263)
[2020-07-17 11:39:34 +0800] [18263] [INFO] Using worker: gevent
[2020-07-17 11:39:34 +0800] [18266] [INFO] Booting worker with pid: 18266
[2020-07-17 11:39:34 +0800] [18267] [INFO] Booting worker with pid: 18267
[2020-10-14 15:21:28 +0800] [29450] [INFO] Booting worker with pid: 29450
[2020-10-14 15:21:28 +0800] [18263] [INFO] Handling signal: term
[2020-10-14 15:21:28 +0800] [29451] [INFO] Booting worker with pid: 29451
[2020-10-14 15:21:30 +0800] [29450] [ERROR] Exception in worker process
Traceback (most recent call last):
  File "/root/flask_python37/lib/python3.7/site-packages/redis/connection.py", line 559, in connect
    sock = self._connect()
  File "/root/flask_python37/lib/python3.7/site-packages/redis/connection.py", line 615, in _connect
    raise err
  File "/root/flask_python37/lib/python3.7/site-packages/redis/connection.py", line 603, in _connect
    sock.connect(socket_address)
  File "/root/flask_python37/lib/python3.7/site-packages/gevent/_socket3.py", line 407, in connect
    raise error(err, strerror(err))
ConnectionRefusedError: [Errno 111] Connection refused

During handling of the above exception, another exception occurred:

Traceback (most recent call last):
  File "/root/flask_python37/lib/python3.7/site-packages/gunicorn/arbiter.py", line 583, in spawn_worker
    worker.init_process()
  File "/root/flask_python37/lib/python3.7/site-packages/gunicorn/workers/ggevent.py", line 162, in init_process
    super().init_process()
  File "/root/flask_python37/lib/python3.7/site-packages/gunicorn/workers/base.py", line 119, in init_process
    self.load_wsgi()
  File "/root/flask_python37/lib/python3.7/site-packages/gunicorn/workers/base.py", line 144, in load_wsgi
    self.wsgi = self.app.wsgi()
  File "/root/flask_python37/lib/python3.7/site-packages/gunicorn/app/base.py", line 67, in wsgi
    self.callable = self.load()
  File "/root/flask_python37/lib/python3.7/site-packages/gunicorn/app/wsgiapp.py", line 49, in load
    return self.load_wsgiapp()
  File "/root/flask_python37/lib/python3.7/site-packages/gunicorn/app/wsgiapp.py", line 39, in load_wsgiapp
    return util.import_app(self.app_uri)
  File "/root/flask_python37/lib/python3.7/site-packages/gunicorn/util.py", line 358, in import_app
    mod = importlib.import_module(module)
  File "/root/flask_python37/lib/python3.7/importlib/__init__.py", line 127, in import_module
    return _bootstrap._gcd_import(name[level:], package, level)
  File "<frozen importlib._bootstrap>", line 1006, in _gcd_import
  File "<frozen importlib._bootstrap>", line 983, in _find_and_load
  File "<frozen importlib._bootstrap>", line 967, in _find_and_load_unlocked
  File "<frozen importlib._bootstrap>", line 677, in _load_unlocked
  File "<frozen importlib._bootstrap_external>", line 728, in exec_module
  File "<frozen importlib._bootstrap>", line 219, in _call_with_frames_removed
  File "/root/flask_python37/web/run.py", line 14, in <module>
    rds.set('foo', 200)
  File "/root/flask_python37/lib/python3.7/site-packages/redis/client.py", line 1801, in set
    return self.execute_command('SET', *pieces)
  File "/root/flask_python37/lib/python3.7/site-packages/redis/client.py", line 898, in execute_command
    conn = self.connection or pool.get_connection(command_name, **options)
  File "/root/flask_python37/lib/python3.7/site-packages/redis/connection.py", line 1192, in get_connection
    connection.connect()
  File "/root/flask_python37/lib/python3.7/site-packages/redis/connection.py", line 563, in connect
    raise ConnectionError(self._error_message(e))
redis.exceptions.ConnectionError: Error 111 connecting to 106.54.227.26:6379. Connection refused.
[2020-10-14 15:21:30 +0800] [29450] [INFO] Worker exiting (pid: 29450)
[2020-10-14 15:21:30 +0800] [29451] [ERROR] Exception in worker process
Traceback (most recent call last):
  File "/root/flask_python37/lib/python3.7/site-packages/redis/connection.py", line 559, in connect
    sock = self._connect()
  File "/root/flask_python37/lib/python3.7/site-packages/redis/connection.py", line 615, in _connect
    raise err
  File "/root/flask_python37/lib/python3.7/site-packages/redis/connection.py", line 603, in _connect
    sock.connect(socket_address)
  File "/root/flask_python37/lib/python3.7/site-packages/gevent/_socket3.py", line 407, in connect
    raise error(err, strerror(err))
ConnectionRefusedError: [Errno 111] Connection refused

During handling of the above exception, another exception occurred:

Traceback (most recent call last):
  File "/root/flask_python37/lib/python3.7/site-packages/gunicorn/arbiter.py", line 583, in spawn_worker
    worker.init_process()
  File "/root/flask_python37/lib/python3.7/site-packages/gunicorn/workers/ggevent.py", line 162, in init_process
    super().init_process()
  File "/root/flask_python37/lib/python3.7/site-packages/gunicorn/workers/base.py", line 119, in init_process
    self.load_wsgi()
  File "/root/flask_python37/lib/python3.7/site-packages/gunicorn/workers/base.py", line 144, in load_wsgi
    self.wsgi = self.app.wsgi()
  File "/root/flask_python37/lib/python3.7/site-packages/gunicorn/app/base.py", line 67, in wsgi
    self.callable = self.load()
  File "/root/flask_python37/lib/python3.7/site-packages/gunicorn/app/wsgiapp.py", line 49, in load
    return self.load_wsgiapp()
  File "/root/flask_python37/lib/python3.7/site-packages/gunicorn/app/wsgiapp.py", line 39, in load_wsgiapp
    return util.import_app(self.app_uri)
  File "/root/flask_python37/lib/python3.7/site-packages/gunicorn/util.py", line 358, in import_app
    mod = importlib.import_module(module)
  File "/root/flask_python37/lib/python3.7/importlib/__init__.py", line 127, in import_module
    return _bootstrap._gcd_import(name[level:], package, level)
  File "<frozen importlib._bootstrap>", line 1006, in _gcd_import
  File "<frozen importlib._bootstrap>", line 983, in _find_and_load
  File "<frozen importlib._bootstrap>", line 967, in _find_and_load_unlocked
  File "<frozen importlib._bootstrap>", line 677, in _load_unlocked
  File "<frozen importlib._bootstrap_external>", line 728, in exec_module
  File "<frozen importlib._bootstrap>", line 219, in _call_with_frames_removed
  File "/root/flask_python37/web/run.py", line 14, in <module>
    rds.set('foo', 200)
  File "/root/flask_python37/lib/python3.7/site-packages/redis/client.py", line 1801, in set
    return self.execute_command('SET', *pieces)
  File "/root/flask_python37/lib/python3.7/site-packages/redis/client.py", line 898, in execute_command
    conn = self.connection or pool.get_connection(command_name, **options)
  File "/root/flask_python37/lib/python3.7/site-packages/redis/connection.py", line 1192, in get_connection
    connection.connect()
  File "/root/flask_python37/lib/python3.7/site-packages/redis/connection.py", line 563, in connect
    raise ConnectionError(self._error_message(e))
redis.exceptions.ConnectionError: Error 111 connecting to 106.54.227.26:6379. Connection refused.
[2020-10-14 15:21:30 +0800] [29451] [INFO] Worker exiting (pid: 29451)
